<?xml version="1.0" encoding="utf-8"?>
<!-- =================================================================================== -->
<!-- |    This document was autogenerated by xacro from rls_robot_v3_description.urdf.xacro | -->
<!-- |    EDITING THIS FILE BY HAND IS NOT RECOMMENDED                                 | -->
<!-- =================================================================================== -->
<!-- 
	RLS robot version 3
 -->
<robot name="rls_robot_v3">
  <link name="world"/>
  <link name="base_link">
    <inertial>
      <origin rpy="0 0 0" xyz="0.00223062005049845 -0.0860921789034845 0.0653078730969134"/>
      <mass value="0.420648081913576"/>
      <inertia ixx="0.000948066990730791" ixy="4.02249708875225E-05" ixz="-7.12558942280454E-06" iyy="0.00179158550854733" iyz="8.11480789637098E-05" izz="0.00215415641805807"/>
    </inertial>
    <visual>
      <origin rpy="0 0 0" xyz="0 0 0"/>
      <geometry>
        <mesh filename="package://rls_robot_v3_description/meshes/base_link.STL"/>
      </geometry>
      <material name="">
        <color rgba="0.796078431372549 0.823529411764706 0.937254901960784 1"/>
      </material>
    </visual>
    <collision>
      <origin rpy="0 0 0" xyz="0 0 0"/>
      <geometry>
        <mesh filename="package://rls_robot_v3_description/meshes/base_link.STL"/>
      </geometry>
    </collision>
  </link>
  <joint name="joint_world" type="fixed">
    <origin rpy="0 0 0" xyz="0 0 0"/>
    <parent link="world"/>
    <child link="base_link"/>
  </joint>
  <link name="shoulder_link">
    <inertial>
      <origin rpy="0 0 0" xyz="-0.00360461983507538 0.0196243579764001 0.0549791913640194"/>
      <mass value="0.917296306384831"/>
      <inertia ixx="0.00372809822859805" ixy="2.35187675560378E-06" ixz="4.15847551263434E-05" iyy="0.00317994476286337" iyz="-0.000578843384303617" izz="0.00237331307162181"/>
    </inertial>
    <visual>
      <origin rpy="0 0 0" xyz="0 0 0"/>
      <geometry>
        <mesh filename="package://rls_robot_v3_description/meshes/shoulder_link.STL"/>
      </geometry>
      <material name="">
        <color rgba="0.796078431372549 0.823529411764706 0.937254901960784 1"/>
      </material>
    </visual>
    <collision>
      <origin rpy="0 0 0" xyz="0 0 0"/>
      <geometry>
        <mesh filename="package://rls_robot_v3_description/meshes/shoulder_link.STL"/>
      </geometry>
    </collision>
  </link>
  <joint name="joint_1" type="revolute">
    <limit effort="1.0" lower="-6.28318530718" upper="6.28318530718" velocity="1.0"/>
    <origin rpy="0 0 0" xyz="0 0 0.055"/>
    <parent link="base_link"/>
    <child link="shoulder_link"/>
    <axis xyz="0 0 1"/>
  </joint>
  <link name="elbow_link">
    <inertial>
      <origin rpy="0 0 0" xyz="0.010518 -0.023536 0.03141"/>
      <mass value="0.41022"/>
      <inertia ixx="0.00070293" ixy="-4.0883E-20" ixz="8.4717E-20" iyy="0.00058841" iyz="-1.2217E-05" izz="0.00014133"/>
    </inertial>
    <visual>
      <origin rpy="0 0 0" xyz="0 0 0"/>
      <geometry>
        <mesh filename="package://rls_robot_v3_description/meshes/elbow_link.STL"/>
      </geometry>
      <material name="">
        <color rgba="0.79608 0.82353 0.93725 1"/>
      </material>
    </visual>
    <collision>
      <origin rpy="0 0 0" xyz="0 0 0"/>
      <geometry>
        <mesh filename="package://rls_robot_v3_description/meshes/elbow_link.STL"/>
      </geometry>
    </collision>
  </link>
  <joint name="joint_2" type="revolute">
    <limit effort="1.0" lower="-2.11184839491" upper="0.314159265359" velocity="1.0"/>
    <origin rpy="0 0 0" xyz="0 0.025 0.15"/>
    <parent link="shoulder_link"/>
    <child link="elbow_link"/>
    <axis xyz="1 0 0"/>
  </joint>
  <link name="wrist_link">
    <inertial>
      <origin rpy="0 0 0" xyz="-0.00517759838399414 -1.12284313791289E-14 0.05914538962879"/>
      <mass value="0.370456595734376"/>
      <inertia ixx="0.000338616717561741" ixy="1.10349781664733E-14" ixz="-4.73908450960823E-05" iyy="0.00031647285637993" iyz="-1.23623627821828E-16" izz="0.000186630647233192"/>
    </inertial>
    <visual>
      <origin rpy="0 0 0" xyz="0 0 0"/>
      <geometry>
        <mesh filename="package://rls_robot_v3_description/meshes/wrist_link.STL"/>
      </geometry>
      <material name="">
        <color rgba="0.796078431372549 0.823529411764706 0.937254901960784 1"/>
      </material>
    </visual>
    <collision>
      <origin rpy="0 0 0" xyz="0 0 0"/>
      <geometry>
        <mesh filename="package://rls_robot_v3_description/meshes/wrist_link.STL"/>
      </geometry>
    </collision>
  </link>
  <joint name="joint_3" type="revolute">
    <limit effort="1.0" lower="-2.07694180987" upper="2.07694180987" velocity="1.0"/>
    <origin rpy="0 0 0" xyz="0 -0.022 0.18"/>
    <parent link="elbow_link"/>
    <child link="wrist_link"/>
    <axis xyz="1 0 0"/>
  </joint>
  <link name="hand_link">
    <inertial>
      <origin rpy="0 0 0" xyz="-0.00796040032027464 -1.60461921527855E-17 0.0239989336979419"/>
      <mass value="0.211251930706032"/>
      <inertia ixx="0.000213040185297751" ixy="2.98830548714608E-21" ixz="-4.03578053376338E-05" iyy="0.000236261133782809" iyz="4.38702711805866E-20" izz="0.000122829629792291"/>
    </inertial>
    <visual>
      <origin rpy="0 0 0" xyz="0 0 0"/>
      <geometry>
        <mesh filename="package://rls_robot_v3_description/meshes/hand_link.STL"/>
      </geometry>
      <material name="">
        <color rgba="0.909803921568627 0.443137254901961 0.0313725490196078 1"/>
      </material>
    </visual>
    <collision>
      <origin rpy="0 0 0" xyz="0 0 0"/>
      <geometry>
        <mesh filename="package://rls_robot_v3_description/meshes/hand_link.STL"/>
      </geometry>
    </collision>
  </link>
  <joint name="joint_4" type="revolute">
    <limit effort="1.0" lower="-1.88495559215" upper="1.88495559215" velocity="1.0"/>
    <origin rpy="0 0 0" xyz="0 0 0.18"/>
    <parent link="wrist_link"/>
    <child link="hand_link"/>
    <axis xyz="1 0 0"/>
  </joint>
  <link name="tool_link">
    <origin rpy="0 0 0" xyz="1.41495086362036E-17 4.33680868994202E-19 0.00500000000000012"/>
  </link>
  <joint name="joint_tool" type="fixed">
    <origin rpy="0 0 0" xyz="0 0 0.065"/>
    <parent link="hand_link"/>
    <child link="tool_link"/>
    <axis xyz="0 0 0"/>
  </joint>
  <!-- TRANSMISSIONS -->
  <transmission name="tran_1">
    <type>transmission_interface/SimpleTransmission</type>
    <joint name="joint_1">
      <hardwareInterface>PositionJointInterface</hardwareInterface>
    </joint>
    <actuator name="motor_1">
      <hardwareInterface>PositionJointInterface</hardwareInterface>
      <mechanicalReduction>21.66</mechanicalReduction>
    </actuator>
  </transmission>
  <transmission name="tran_2">
    <type>transmission_interface/SimpleTransmission</type>
    <joint name="joint_2">
      <hardwareInterface>PositionJointInterface</hardwareInterface>
    </joint>
    <actuator name="motor_2">
      <hardwareInterface>PositionJointInterface</hardwareInterface>
      <mechanicalReduction>20.01</mechanicalReduction>
    </actuator>
  </transmission>
  <transmission name="tran_3">
    <type>transmission_interface/SimpleTransmission</type>
    <joint name="joint_3">
      <hardwareInterface>PositionJointInterface</hardwareInterface>
    </joint>
    <actuator name="motor_3">
      <hardwareInterface>PositionJointInterface</hardwareInterface>
      <mechanicalReduction>20.01</mechanicalReduction>
    </actuator>
  </transmission>
  <transmission name="tran_4">
    <type>transmission_interface/SimpleTransmission</type>
    <joint name="joint_4">
      <hardwareInterface>PositionJointInterface</hardwareInterface>
    </joint>
    <actuator name="motor_4">
      <hardwareInterface>PositionJointInterface</hardwareInterface>
      <mechanicalReduction>18.13</mechanicalReduction>
    </actuator>
  </transmission>
</robot>

